<?xml version="1.0"?>
<robot name="myfirst">

  <material name="trans">
    <color rgba="1 1 1 0.5"/>
  </material>
  
  <material name="yellow">
    <color rgba="1 1 0.1 1"/>
  </material>
  
  <material name="black">
    <color rgba="0 0 0 1"/>
  </material>

<!-- *****************************************-->
<!-- Chassis -->
<!-- *****************************************-->
  <link name="base_link">
    <visual>
      <geometry>
        <cylinder length="0.0025" radius="0.07"/>
      </geometry>
      <material name="trans"/>
      <origin rpy="0 0 0" xyz="0 0 0.0395"/>
    </visual>
    <!-- collision currently the same size as the corpus /-->
    <collision>
      <geometry>
        <cylinder length="0.0025" radius="0.07"/>
      </geometry>
    </collision>
    <!-- Physical constraints -->
    <inertial>
       <mass value="0.5"/>
	 <inertia ixx="0.4" ixy="0.0" ixz="0.0" iyy="0.4" iyz="0.0" izz="0.2"/>
    </inertial>
  </link>

<!-- *****************************************-->
<!-- right wheel -->
<!-- *****************************************-->

  <link name="right_wheel">
    <visual>
      <geometry>
        <cylinder length="0.025" radius="0.0335"/>
      </geometry>
      <material name="yellow"/>
      <!--origin rpy="1.5708 0 0" xyz="0 0.062 0.0335"/-->
      <origin rpy="1.5708 0 0" xyz="0 0 0"/>
    </visual>
    <collision>
      <geometry>
        <cylinder length="0.025" radius="0.0335"/>
	<origin rpy="1.5708 0 0" xyz="0 0 0"/>
      </geometry>
    </collision>
  </link>
  <joint name="base_to_right_wheel" type="fixed">
     <parent link="base_link"/>
     <child link="right_wheel"/>
     <origin xyz="0 0.062 0.0335"/>
  </joint>


<!-- *****************************************-->
<!-- left wheel -->
<!-- *****************************************-->

  <link name="left_wheel">
    <visual>
      <geometry>
        <cylinder length="0.025" radius="0.0335"/>
      </geometry>
      <material name="yellow"/>
      <!--origin rpy="1.5708 0 0" xyz="0 -0.062 0.0335"/-->
      <origin rpy="1.5708 0 0" xyz="0 0 0"/>
    </visual>
    <collision>
      <geometry>
        <cylinder length="0.025" radius="0.0335"/>
	<origin rpy="1.5708 0 0" xyz="0 0 0"/>
      </geometry>
    </collision>
  </link>
  <joint name="base_to_left_wheel" type="fixed">
     <parent link="base_link"/>
     <child link="left_wheel"/>
     <origin xyz="0 -0.062 0.0335"/>
  </joint>
  

<!-- *****************************************-->
<!-- Front wheel -->
<!-- *****************************************-->

  <link name="front_roll">
    <visual>
      <geometry>
        <sphere radius="0.0125"/>
      </geometry>
      <material name="black"/>
      <origin xyz="0 0 0.00625"/>
    </visual>
  </link>
  <joint name="base_to_front_roll" type="continuous">
     <parent link="base_link"/>
     <child link="front_roll"/>
     <origin xyz="0.038 0 0"/>
     <axis xyz="0 0 1"/>
  </joint>

<!-- *****************************************-->
<!-- rear wheel -->
<!-- *****************************************-->
 <link name="rear_roll">
    <visual>
      <geometry>
        <sphere radius="0.0125"/>
      </geometry>
      <material name="black"/>
      <origin xyz="0 0 0.00625"/>
    </visual>
  </link>
  <joint name="base_to_rear_roll" type="continuous">
     <parent link="base_link"/>
     <child link="rear_roll"/>
     <origin xyz="-0.038 0 0"/>
     <axis xyz="0 0 1"/>
  </joint>
<!-- *****************************************-->
<!-- Gazebo -->
<!-- *****************************************-->

  <gazebo>
    <plugin name="gazebo_ros_control" filename="libgazebo_ros_control.so">
       <robotNamespace>/</robotNamespace>
    </plugin>
  </gazebo>


</robot>
